Workbook
Name \a: #REF!
Name \AA: #REF!
Name \AH: #REF!
Name \b: #REF!
Name \f: #REF!
Name \FO: #REF!
Name \MS: #REF!
Name \n: #REF!
Name \o: #REF!
Name \p: #REF!
Name \q: #REF!
Name \r: #REF!
Name \RK: #REF!
Name \s: #REF!
Name \SM: #REF!
Name \SO: #REF!
Name \TOT: #REF!
Name \v: #REF!
Name \z: #REF!
Name \ZD: #REF!
Name ____pa2: #REF!
Name ___LLT1: #REF!
Name ___LLT10: #REF!
Name ___LLT11: #REF!
Name ___LLT12: #REF!
Name ___LLT2: #REF!
Name ___LLT3: #REF!
Name ___LLT4: #REF!
Name ___LLT5: #REF!
Name ___LLT6: #REF!
Name ___LLT7: #REF!
Name ___LLT8: #REF!
Name ___LLT9: #REF!
Name ___LST1: #REF!
Name ___LST2: #REF!
Name ___LST3: #REF!
Name ___LST4: #REF!
Name ___LST5: #REF!
Name ___LT1: #REF!
Name ___LT2: #REF!
Name ___LT3: #REF!
Name ___LT4: #REF!
Name ___pa2: #REF!
Name ___STX1: #REF!
Name ___STX2: #REF!
Name ___STX3: #REF!
Name ___STX4: #REF!
Name ___STX5: #REF!
Name ___tot67000: #REF!
Name __Dat1: #REF!
Name __LLT1: #REF!
Name __LLT10: #REF!
Name __LLT11: #REF!
Name __LLT12: #REF!
Name __LLT2: #REF!
Name __LLT3: #REF!
Name __LLT4: #REF!
Name __LLT5: #REF!
Name __LLT6: #REF!
Name __LLT7: #REF!

Sheet BOQs
M1: =SUBTOTAL(9,tbl_BOQs[Total]) -> 5134038.8
A2: Unique | B2: type | C2: ID_Contractor | D2: BOQ ID | E2: Contractor | F2: ItemEN | G2: Item_AR | H2: ItemEN1 | I2: Item_AR1 | J2: Unit | K2: Quantities | L2: Cost | M2: Total | R2: Row Labels | S2: Sum of Total
A3: =tbl_BOQs[[#This Row],[BOQ ID]]&"-"&tbl_BOQs[[#This Row],[Contractor]] -> w1_1-C3 | B3: Room and external finishing works | C3: 01 | D3: w1_1 | E3: C3 | F3: 1.1 Light demolition with hand tools | G3: 1.1 أعمال هدم بسيط بالأدوات اليدوية | H3: 1.1 Light demolition with hand tools | I3: 1.1 أعمال هدم بسيط بالأدوات اليدوية | K3: 5803 | L3: 7 | M3: =tbl_BOQs[[#This Row],[Cost]]*tbl_BOQs[[#This Row],[Quantities]] -> 40621 | R3: Rehabilitation | S3: 2623
A4: =tbl_BOQs[[#This Row],[BOQ ID]]&"-"&tbl_BOQs[[#This Row],[Contractor]] -> w1_2-C3 | B4: Room and external finishing works | C4: 02 | D4: w1_2 | E4: C3 | F4: 1.2 Debris removal | G4: 1.2 إزالة الأنقاض | H4: 1.2 Debris removal | I4: 1.2 إزالة الأنقاض | K4: 5803 | L4: 6 | M4: =tbl_BOQs[[#This Row],[Cost]]*tbl_BOQs[[#This Row],[Quantities]] -> 34818 | R4: Grand Total | S4: 2623
A5: =tbl_BOQs[[#This Row],[BOQ ID]]&"-"&tbl_BOQs[[#This Row],[Contractor]] -> w1_3-C3 | B5: Room and external finishing works | C5: 03 | D5: w1_3 | E5: C3 | F5: 1.3 Blockwork | G5: 1.3 أعمال بناء البلوك | H5: 1.3 Blockwork | I5: 1.3 أعمال بناء البلوك | K5: 5803 | L5: 75 | M5: =tbl_BOQs[[#This Row],[Cost]]*tbl_BOQs[[#This Row],[Quantities]] -> 435225
A6: =tbl_BOQs[[#This Row],[BOQ ID]]&"-"&tbl_BOQs[[#This Row],[Contractor]] -> w1_4-C3 | B6: Room and external finishing works | C6: 04 | D6: w1_4 | E6: C3 | F6: 1.4 Concrete floor repair without formwork (250 kg/m³) | G6: 1.4 تصليح الأرضيات بالبيتون بدون قالب (250 كغ/م³) | H6: 1.4 Concrete floor repair without formwork (250 kg/m³) | I6: 1.4 تصليح الأرضيات بالبيتون بدون قالب (250 كغ/م³) | K6: 5803 | L6: 75 | M6: =tbl_BOQs[[#This Row],[Cost]]*tbl_BOQs[[#This Row],[Quantities]] -> 435225
A7: =tbl_BOQs[[#This Row],[BOQ ID]]&"-"&tbl_BOQs[[#This Row],[Contractor]] -> w1_5-C3 | B7: Room and external finishing works | C7: 05 | D7: w1_5 | E7: C3 | F7: 1.5 Concrete roof repair with formwork (350 kg/m³) | G7: 1.5 تصليح الأسقف بالبيتون مع القالب (350 كغ/م³) | H7: 1.5 Concrete roof repair with formwork (350 kg/m³) | I7: 1.5 تصليح الأسقف بالبيتون مع القالب (350 كغ/م³) | K7: 5803 | L7: 148 | M7: =tbl_BOQs[[#This Row],[Cost]]*tbl_BOQs[[#This Row],[Quantities]] -> 858844
A8: =tbl_BOQs[[#This Row],[BOQ ID]]&"-"&tbl_BOQs[[#This Row],[Contractor]] -> w1_6-C3 | B8: Room and external finishing works | C8: 06 | D8: w1_6 | E8: C3 | F8: 1.6 Plastering for walls and ceilings | G8: 1.6 أعمال الطينة للجدران والأسقف | H8: 1.6 Plastering for walls and ceilings | I8: 1.6 أعمال الطينة للجدران والأسقف | K8: 9000 | L8: 5 | M8: =tbl_BOQs[[#This Row],[Cost]]*tbl_BOQs[[#This Row],[Quantities]] -> 45000
A9: =tbl_BOQs[[#This Row],[BOQ ID]]&"-"&tbl_BOQs[[#This Row],[Contractor]] -> w1_7-C3 | B9: Room and external finishing works | C9: 07 | D9: w1_7 | E9: C3 | F9: 1.7 Repair existing doors & windows with paint | G9: 1.7 صيانة الأبواب والنوافذ الموجودة مع الدهان | H9: 1.7 Repair existing doors & windows with paint | I9: 1.7 صيانة الأبواب والنوافذ الموجودة مع الدهان | K9: 2650 | L9: 25 | M9: =tbl_BOQs[[#This Row],[Cost]]*tbl_BOQs[[#This Row],[Quantities]] -> 66250
A10: =tbl_BOQs[[#This Row],[BOQ ID]]&"-"&tbl_BOQs[[#This Row],[Contractor]] -> w1_8-C3 | B10: Room and external finishing works | C10: 08 | D10: w1_8 | E10: C3 | F10: 1.8 Install clear/frosted glass for doors and windows | G10: 1.8 تركيب زجاج عادي أو مجلتن للنوافذ والأبواب | H10: 1.8 Install clear/frosted glass for doors and windows | I10: 1.8 تركيب زجاج عادي أو مجلتن للنوافذ والأبواب | K10: 528 | L10: 10 | M10: =tbl_BOQs[[#This Row],[Cost]]*tbl_BOQs[[#This Row],[Quantities]] -> 5280
A11: =tbl_BOQs[[#This Row],[BOQ ID]]&"-"&tbl_BOQs[[#This Row],[Contractor]] -> w1_9-C3 | B11: Room and external finishing works | C11: 09 | D11: w1_9 | E11: C3 | F11: 1.9 Supply & install wooden joinery with accessories | G11: 1.9 تقديم وتركيب منجور خشبي مع الإكسسوارات | H11: 1.9 Supply & install wooden joinery with accessories | I11: 1.9 تقديم وتركيب منجور خشبي مع الإكسسوارات | K11: 2150 | L11: 77 | M11: =tbl_BOQs[[#This Row],[Cost]]*tbl_BOQs[[#This Row],[Quantities]] -> 165550
A12: =tbl_BOQs[[#This Row],[BOQ ID]]&"-"&tbl_BOQs[[#This Row],[Contractor]] -> w1_10-C3 | B12: Room and external finishing works | C12: 10 | D12: w1_10 | E12: C3 | F12: 1.10 Supply & install metal joinery with glass | G12: 1.10 تقديم وتركيب منجور معدني مع الزجاج | H12: 1.10 Supply & install metal joinery with glass | I12: 1.10 تقديم وتركيب منجور معدني مع الزجاج | K12: 11500 | L12: 1.6 | M12: =tbl_BOQs[[#This Row],[Cost]]*tbl_BOQs[[#This Row],[Quantities]] -> 18400
A13: =tbl_BOQs[[#This Row],[BOQ ID]]&"-"&tbl_BOQs[[#This Row],[Contractor]] -> w1_11-C3 | B13: Room and external finishing works | C13: 11 | D13: w1_11 | E13: C3 | F13: 1.11 Supply & install PVC joinery | G13: 1.11 تقديم وتركيب منجور PVC | H13: 1.11 Supply & install PVC joinery | I13: 1.11 تقديم وتركيب منجور PVC | K13: 6200 | L13: 42 | M13: =tbl_BOQs[[#This Row],[Cost]]*tbl_BOQs[[#This Row],[Quantities]] -> 260400
A14: =tbl_BOQs[[#This Row],[BOQ ID]]&"-"&tbl_BOQs[[#This Row],[Contractor]] -> w1_12-C3 | B14: Room and external finishing works | C14: 12 | D14: w1_12 | E14: C3 | F14: 1.12 Install 3 cm marble door thresholds | G14: 1.12 تركيب وزرة رخام للأبواب (سماكة 3 سم) | H14: 1.12 Install 3 cm marble door thresholds | I14: 1.12 تركيب وزرة رخام للأبواب (سماكة 3 سم) | K14: 51 | L14: 6 | M14: =tbl_BOQs[[#This Row],[Cost]]*tbl_BOQs[[#This Row],[Quantities]] -> 306
A15: =tbl_BOQs[[#This Row],[BOQ ID]]&"-"&tbl_BOQs[[#This Row],[Contractor]] -> w1_13-C3 | B15: Room and external finishing works | C15: 13 | D15: w1_13 | E15: C3 | F15: 1.13 Install stainless steel handrails for PWD | G15: 1.13 تركيب درابزونات ستانلس ستيل لذوي الاحتياجات الخاصة | H15: 1.13 Install stainless steel handrails for PWD | I15: 1.13 تركيب درابزونات ستانلس ستيل لذوي الاحتياجات الخاصة | K15: 49 | L15: 9 | M15: =tbl_BOQs[[#This Row],[Cost]]*tbl_BOQs[[#This Row],[Quantities]] -> 441
A16: =tbl_BOQs[[#This Row],[BOQ ID]]&"-"&tbl_BOQs[[#This Row],[Contractor]] -> w1_14-C3 | B16: Room and external finishing works | C16: 14 | D16: w1_14 | E16: C3 | F16: 1.14 Construct ramp for PWD | G16: 1.14 إنشاء رامب لذوي الاحتياجات الخاصة | H16: 1.14 Construct ramp for PWD | I16: 1.14 إنشاء رامب لذوي الاحتياجات الخاصة | K16: 32 | L16: 20 | M16: =tbl_BOQs[[#This Row],[Cost]]*tbl_BOQs[[#This Row],[Quantities]] -> 640
A17: =tbl_BOQs[[#This Row],[BOQ ID]]&"-"&tbl_BOQs[[#This Row],[Contractor]] -> w2_1-C3 | B17: Kitchen and wet area works | C17: 15 | D17: w2_1 | E17: C3 | F17: 2.1 Install chrome water mixer with brass core | G17: 2.1 تركيب خلاط مياه كروم مع قلب نحاسي | H17: 2.1 Install chrome water mixer with brass core | I17: 2.1 تركيب خلاط مياه كروم مع قلب نحاسي | K17: 166 | L17: 20 | M17: =tbl_BOQs[[#This Row],[Cost]]*tbl_BOQs[[#This Row],[Quantities]] -> 3320
A18: =tbl_BOQs[[#This Row],[BOQ ID]]&"-"&tbl_BOQs[[#This Row],[Contractor]] -> w2_2-C3 | B18: Kitchen and wet area works | C18: 16 | D18: w2_2 | E18: C3 | F18: 2.2 Install ceramic floor tiles | G18: 2.2 تركيب سيراميك للأرضيات | H18: 2.2 Install ceramic floor tiles | I18: 2.2 تركيب سيراميك للأرضيات | K18: 650 | L18: 18 | M18: =tbl_BOQs[[#This Row],[Cost]]*tbl_BOQs[[#This Row],[Quantities]] -> 11700
A19: =tbl_BOQs[[#This Row],[BOQ ID]]&"-"&tbl_BOQs[[#This Row],[Contractor]] -> w2_3-C3 | B19: Kitchen and wet area works | C19: 17 | D19: w2_3 | E19: C3 | F19: 2.3 Install ceramic wall tiles | G19: 2.3 تركيب سيراميك للجدران | H19: 2.3 Install ceramic wall tiles | I19: 2.3 تركيب سيراميك للجدران | K19: 650 | L19: 18 | M19: =tbl_BOQs[[#This Row],[Cost]]*tbl_BOQs[[#This Row],[Quantities]] -> 11700
A20: =tbl_BOQs[[#This Row],[BOQ ID]]&"-"&tbl_BOQs[[#This Row],[Contractor]] -> w2_4-C3 | B20: Kitchen and wet area works | C20: 18 | D20: w2_4 | E20: C3 | F20: 2.4 Install 2.2m mosaic sink with stone splashback | G20: 2.4 تركيب مجلى موزاييك (2.2 م) مع وقافيات حجر | H20: 2.4 Install 2.2m mosaic sink with stone splashback | I20: 2.4 تركيب مجلى موزاييك (2.2 م) مع وقافيات حجر | K20: 164 | L20: 70 | M20: =tbl_BOQs[[#This Row],[Cost]]*tbl_BOQs[[#This Row],[Quantities]] -> 11480
A21: =tbl_BOQs[[#This Row],[BOQ ID]]&"-"&tbl_BOQs[[#This Row],[Contractor]] -> w2_5-C3 | B21: Kitchen and wet area works | C21: 19 | D21: w2_5 | E21: C3 | F21: 2.5 Install squat toilet | G21: 2.5 تركيب مرحاض أرضي (بطة) | H21: 2.5 Install squat toilet | I21: 2.5 تركيب مرحاض أرضي (بطة) | K21: 32 | L21: 40 | M21: =tbl_BOQs[[#This Row],[Cost]]*tbl_BOQs[[#This Row],[Quantities]] -> 1280
A22: =tbl_BOQs[[#This Row],[BOQ ID]]&"-"&tbl_BOQs[[#This Row],[Contractor]] -> w2_6-C3 | B22: Kitchen and wet area works | C22: 20 | D22: w2_6 | E22: C3 | F22: 2.6 Install WC toilet | G22: 2.6 تركيب كرسي تواليت | H22: 2.6 Install WC toilet | I22: 2.6 تركيب كرسي تواليت | K22: 65 | L22: 100 | M22: =tbl_BOQs[[#This Row],[Cost]]*tbl_BOQs[[#This Row],[Quantities]] -> 6500
A23: =tbl_BOQs[[#This Row],[BOQ ID]]&"-"&tbl_BOQs[[#This Row],[Contractor]] -> w2_7-C3 | B23: Kitchen and wet area works | C23: 21 | D23: w2_7 | E23: C3 | F23: 2.7 Install single water tap with brass core | G23: 2.7 تركيب حنفية مياه مفردة مع قلب نحاسي | H23: 2.7 Install single water tap with brass core | I23: 2.7 تركيب حنفية مياه مفردة مع قلب نحاسي | K23: 480 | L23: 7 | M23: =tbl_BOQs[[#This Row],[Cost]]*tbl_BOQs[[#This Row],[Quantities]] -> 3360
... A45: =tbl_BOQs[[#This Row],[BOQ ID]]&"-"&tbl_BOQs[[#This Row],[Contractor]] -> w6_1-C3 | B45: Roof insulation works | C45: 43 | D45: w6_1 | E45: C3 | F45: 6.1 Acrylic elastic roof waterproofing | G45: 6.1 عزل مطاطي (أكريليك) للأسطح | H45: 6.1 Acrylic elastic roof waterproofing | I45: 6.1 عزل مطاطي (أكريليك) للأسطح | K45: 29226 | L45: 1.7 | M45: =tbl_BOQs[[#This Row],[Cost]]*tbl_BOQs[[#This Row],[Quantities]] -> 49684.2
A46: =tbl_BOQs[[#This Row],[BOQ ID]]&"-"&tbl_BOQs[[#This Row],[Contractor]] -> w1_1-C1 | B46: Room and external finishing works | C46: 01 | D46: w1_1 | E46: C1 | F46: 1.1 Light demolition with hand tools | G46: 1.1 أعمال هدم بسيط بالأدوات اليدوية | H46: 1.1 Light demolition with hand tools | I46: 1.1 أعمال هدم بسيط بالأدوات اليدوية | K46: 5803 | L46: 1.2 | M46: =tbl_BOQs[[#This Row],[Cost]]*tbl_BOQs[[#This Row],[Quantities]] -> 6963.6
A47: =tbl_BOQs[[#This Row],[BOQ ID]]&"-"&tbl_BOQs[[#This Row],[Contractor]] -> w1_2-C1 | B47: Room and external finishing works | C47: 02 | D47: w1_2 | E47: C1 | F47: 1.2 Debris removal | G47: 1.2 إزالة الأنقاض | H47: 1.2 Debris removal | I47: 1.2 إزالة الأنقاض | K47: 5803 | L47: 5 | M47: =tbl_BOQs[[#This Row],[Cost]]*tbl_BOQs[[#This Row],[Quantities]] -> 29015
A48: =tbl_BOQs[[#This Row],[BOQ ID]]&"-"&tbl_BOQs[[#This Row],[Contractor]] -> w1_3-C1 | B48: Room and external finishing works | C48: 03 | D48: w1_3 | E48: C1 | F48: 1.3 Blockwork | G48: 1.3 أعمال بناء البلوك | H48: 1.3 Blockwork | I48: 1.3 أعمال بناء البلوك | K48: 5803 | L48: 78 | M48: =tbl_BOQs[[#This Row],[Cost]]*tbl_BOQs[[#This Row],[Quantities]] -> 452634
A49: =tbl_BOQs[[#This Row],[BOQ ID]]&"-"&tbl_BOQs[[#This Row],[Contractor]] -> w1_4-C1 | B49: Room and external finishing works | C49: 04 | D49: w1_4 | E49: C1 | F49: 1.4 Concrete floor repair without formwork (250 kg/m³) | G49: 1.4 تصليح الأرضيات بالبيتون بدون قالب (250 كغ/م³) | H49: 1.4 Concrete floor repair without formwork (250 kg/m³) | I49: 1.4 تصليح الأرضيات بالبيتون بدون قالب (250 كغ/م³) | K49: 5803 | L49: 60 | M49: =tbl_BOQs[[#This Row],[Cost]]*tbl_BOQs[[#This Row],[Quantities]] -> 348180
A50: =tbl_BOQs[[#This Row],[BOQ ID]]&"-"&tbl_BOQs[[#This Row],[Contractor]] -> w1_5-C1 | B50: Room and external finishing works | C50: 05 | D50: w1_5 | E50: C1 | F50: 1.5 Concrete roof repair with formwork (350 kg/m³) | G50: 1.5 تصليح الأسقف بالبيتون مع القالب (350 كغ/م³) | H50: 1.5 Concrete roof repair with formwork (350 kg/m³) | I50: 1.5 تصليح الأسقف بالبيتون مع القالب (350 كغ/م³) | K50: 5803 | L50: 138 | M50: =tbl_BOQs[[#This Row],[Cost]]*tbl_BOQs[[#This Row],[Quantities]] -> 800814
A51: =tbl_BOQs[[#This Row],[BOQ ID]]&"-"&tbl_BOQs[[#This Row],[Contractor]] -> w1_6-C1 | B51: Room and external finishing works | C51: 06 | D51: w1_6 | E51: C1 | F51: 1.6 Plastering for walls and ceilings | G51: 1.6 أعمال الطينة للجدران والأسقف | H51: 1.6 Plastering for walls and ceilings | I51: 1.6 أعمال الطينة للجدران والأسقف | K51: 9000 | L51: 4.5 | M51: =tbl_BOQs[[#This Row],[Cost]]*tbl_BOQs[[#This Row],[Quantities]] -> 40500
A52: =tbl_BOQs[[#This Row],[BOQ ID]]&"-"&tbl_BOQs[[#This Row],[Contractor]] -> w1_7-C1 | B52: Room and external finishing works | C52: 07 | D52: w1_7 | E52: C1 | F52: 1.7 Repair existing doors & windows with paint | G52: 1.7 صيانة الأبواب والنوافذ الموجودة مع الدهان | H52: 1.7 Repair existing doors & windows with paint | I52: 1.7 صيانة الأبواب والنوافذ الموجودة مع الدهان | K52: 2650 | L52: 20 | M52: =tbl_BOQs[[#This Row],[Cost]]*tbl_BOQs[[#This Row],[Quantities]] -> 53000
A53: =tbl_BOQs[[#This Row],[BOQ ID]]&"-"&tbl_BOQs[[#This Row],[Contractor]] -> w1_8-C1 | B53: Room and external finishing works | C53: 08 | D53: w1_8 | E53: C1 | F53: 1.8 Install clear/frosted glass for doors and windows | G53: 1.8 تركيب زجاج عادي أو مجلتن للنوافذ والأبواب | H53: 1.8 Install clear/frosted glass for doors and windows | I53: 1.8 تركيب زجاج عادي أو مجلتن للنوافذ والأبواب | K53: 528 | L53: 10 | M53: =tbl_BOQs[[#This Row],[Cost]]*tbl_BOQs[[#This Row],[Quantities]] -> 5280
A54: =tbl_BOQs[[#This Row],[BOQ ID]]&"-"&tbl_BOQs[[#This Row],[Contractor]] -> w1_9-C1 | B54: Room and external finishing works | C54: 09 | D54: w1_9 | E54: C1 | F54: 1.9 Supply & install wooden joinery with accessories | G54: 1.9 تقديم وتركيب منجور خشبي مع الإكسسوارات | H54: 1.9 Supply & install wooden joinery with accessories | I54: 1.9 تقديم وتركيب منجور خشبي مع الإكسسوارات | K54: 2150 | L54: 64 | M54: =tbl_BOQs[[#This Row],[Cost]]*tbl_BOQs[[#This Row],[Quantities]] -> 137600
A55: =tbl_BOQs[[#This Row],[BOQ ID]]&"-"&tbl_BOQs[[#This Row],[Contractor]] -> w1_10-C1 | B55: Room and external finishing works | C55: 10 | D55: w1_10 | E55: C1 | F55: 1.10 Supply & install metal joinery with glass | G55: 1.10 تقديم وتركيب منجور معدني مع الزجاج | H55: 1.10 Supply & install metal joinery with glass | I55: 1.10 تقديم وتركيب منجور معدني مع الزجاج | K55: 11500 | L55: 3 | M55: =tbl_BOQs[[#This Row],[Cost]]*tbl_BOQs[[#This Row],[Quantities]] -> 34500
A56: =tbl_BOQs[[#This Row],[BOQ ID]]&"-"&tbl_BOQs[[#This Row],[Contractor]] -> w1_11-C1 | B56: Room and external finishing works | C56: 11 | D56: w1_11 | E56: C1 | F56: 1.11 Supply & install PVC joinery | G56: 1.11 تقديم وتركيب منجور PVC | H56: 1.11 Supply & install PVC joinery | I56: 1.11 تقديم وتركيب منجور PVC | K56: 6200 | L56: 56 | M56: =tbl_BOQs[[#This Row],[Cost]]*tbl_BOQs[[#This Row],[Quantities]] -> 347200
A57: =tbl_BOQs[[#This Row],[BOQ ID]]&"-"&tbl_BOQs[[#This Row],[Contractor]] -> w1_12-C1 | B57: Room and external finishing works | C57: 12 | D57: w1_12 | E57: C1 | F57: 1.12 Install 3 cm marble door thresholds | G57: 1.12 تركيب وزرة رخام للأبواب (سماكة 3 سم) | H57: 1.12 Install 3 cm marble door thresholds | I57: 1.12 تركيب وزرة رخام للأبواب (سماكة 3 سم) | K57: 51 | L57: 10 | M57: =tbl_BOQs[[#This Row],[Cost]]*tbl_BOQs[[#This Row],[Quantities]] -> 510
A58: =tbl_BOQs[[#This Row],[BOQ ID]]&"-"&tbl_BOQs[[#This Row],[Contractor]] -> w1_13-C1 | B58: Room and external finishing works | C58: 13 | D58: w1_13 | E58: C1 | F58: 1.13 Install stainless steel handrails for PWD | G58: 1.13 تركيب درابزونات ستانلس ستيل لذوي الاحتياجات الخاصة | H58: 1.13 Install stainless steel handrails for PWD | I58: 1.13 تركيب درابزونات ستانلس ستيل لذوي الاحتياجات الخاصة | K58: 49 | L58: 20 | M58: =tbl_BOQs[[#This Row],[Cost]]*tbl_BOQs[[#This Row],[Quantities]] -> 980
A59: =tbl_BOQs[[#This Row],[BOQ ID]]&"-"&tbl_BOQs[[#This Row],[Contractor]] -> w1_14-C1 | B59: Room and external finishing works | C59: 14 | D59: w1_14 | E59: C1 | F59: 1.14 Construct ramp for PWD | G59: 1.14 إنشاء رامب لذوي الاحتياجات الخاصة | H59: 1.14 Construct ramp for PWD | I59: 1.14 إنشاء رامب لذوي الاحتياجات الخاصة | K59: 32 | L59: 20 | M59: =tbl_BOQs[[#This Row],[Cost]]*tbl_BOQs[[#This Row],[Quantities]] -> 640
A60: =tbl_BOQs[[#This Row],[BOQ ID]]&"-"&tbl_BOQs[[#This Row],[Contractor]] -> w2_1-C1 | B60: Kitchen and wet area works | C60: 15 | D60: w2_1 | E60: C1 | F60: 2.1 Install chrome water mixer with brass core | G60: 2.1 تركيب خلاط مياه كروم مع قلب نحاسي | H60: 2.1 Install chrome water mixer with brass core | I60: 2.1 تركيب خلاط مياه كروم مع قلب نحاسي | K60: 166 | L60: 23 | M60: =tbl_BOQs[[#This Row],[Cost]]*tbl_BOQs[[#This Row],[Quantities]] -> 3818
A61: =tbl_BOQs[[#This Row],[BOQ ID]]&"-"&tbl_BOQs[[#This Row],[Contractor]] -> w2_2-C1 | B61: Kitchen and wet area works | C61: 16 | D61: w2_2 | E61: C1 | F61: 2.2 Install ceramic floor tiles | G61: 2.2 تركيب سيراميك للأرضيات | H61: 2.2 Install ceramic floor tiles | I61: 2.2 تركيب سيراميك للأرضيات | K61: 650 | L61: 12 | M61: =tbl_BOQs[[#This Row],[Cost]]*tbl_BOQs[[#This Row],[Quantities]] -> 7800
...

Sheet Contractors
A1: # | B1: Code | C1: Type | D1: Company EN | E1: Ceiling amount of this contract
A2: 1 | B2: C1 | C2: Rehabilitation
B3: C2
B4: C3

Sheet List
B3: Data Entry | D3: رقم | E3: الحالة بالعربية | F3: الحالة بالإنجليزية | G3: الوصف المختصر | H3: Damage | I3: كود اللون | K3: Code | L3: item_ar | M3: item_en
B4: مصطفى خطاب | D4: 1 | E4: لا يوجد ضرر أو ضرر طفيف جدًا | F4: No or Negligible Damage | G4: لا يوجد ضرر إنشائي، المبنى آمن ووظيفي بالكامل | H4: =tbl_Damage[[#This Row],[الحالة بالإنجليزية]]&"/"&tbl_Damage[[#This Row],[الحالة بالعربية]] -> No or Negligible Damage/لا يوجد ضرر أو ضرر طفيف جدًا | I4: 🟩 #00B050 | K4: main_1 | L4: أعمال الغرف والتشطيبات الخارجية | M4: Room and external finishing works
B5: فادي عموري | D5: 2 | E5: ضرر خفيف | F5: Minor Damage | G5: أضرار سطحية في بعض الجدران أو الأبواب أو النوافذ دون تأثير على السلامة | H5: =tbl_Damage[[#This Row],[الحالة بالإنجليزية]]&"/"&tbl_Damage[[#This Row],[الحالة بالعربية]] -> Minor Damage/ضرر خفيف | I5: 🟩 #92D050 | K5: main_2 | L5: أعمال المطبخ ودورات المياه | M5: Kitchen and wet area works
B6: احمد الصالح | D6: 3 | E6: ضرر متوسط | F6: Moderate Damage | G6: أضرار متوسطة في الجدران أو الفتحات؛ الهيكل الإنشائي سليم جزئيًا | H6: =tbl_Damage[[#This Row],[الحالة بالإنجليزية]]&"/"&tbl_Damage[[#This Row],[الحالة بالعربية]] -> Moderate Damage/ضرر متوسط | I6: 🟧 #FFC000 | K6: main_3 | L6: أعمال الكهرباء | M6: Electrical works
B7: محمد برهوم | D7: 4 | E7: ضرر شديد | F7: Heavy Damage | G7: بعض العناصر الإنشائية تضررت؛ المبنى غير آمن جزئيًا | H7: =tbl_Damage[[#This Row],[الحالة بالإنجليزية]]&"/"&tbl_Damage[[#This Row],[الحالة بالعربية]] -> Heavy Damage/ضرر شديد | I7: 🟠 #ED7D31 | K7: main_4 | L7: أعمال التمديدات الصحية والسباكة | M7: Sanitary and drainage works
B8: عبد الرزاق بكور | D8: 5 | E8: ضرر بالغ | F8: Severe Damage | G8: أضرار إنشائية واسعة تتطلب إصلاحات كبيرة؛ المبنى غير آمن | H8: =tbl_Damage[[#This Row],[الحالة بالإنجليزية]]&"/"&tbl_Damage[[#This Row],[الحالة بالعربية]] -> Severe Damage/ضرر بالغ | I8: 🟥 #C00000 | K8: main_5 | L8: تمديدات المياه الحلوة | M8: Fresh water supply works
B9: عمر خليفة | D9: 6 | E9: مهدوم | F9: Destroyed | G9: انهيار كلي أو شبه كلي للمبنى؛ غير صالح للسكن | H9: =tbl_Damage[[#This Row],[الحالة بالإنجليزية]]&"/"&tbl_Damage[[#This Row],[الحالة بالعربية]] -> Destroyed/مهدوم | I9: ⬛ #000000 | K9: main_6 | L9: أعمال عزل الأسطح | M9: Roof insulation works
B10: عبد القادر سرحان
B11: فرزت حميدي
B12: احمد عيدي
D13: رقم | E13: الحالة بالعربية | F13: الحالة بالإنجليزية | G13: الوصف المختصر | H13: Assessment_Status | I13: كود اللون
B14: Activity Name | D14: 1 | E14: مقبول | F14: Accepted | G14: تمت الموافقة على الحالة دون شروط إضافية | H14: =tbl_Assessment_Status[[#This Row],[الحالة بالإنجليزية]]&"/"&tbl_Assessment_Status[[#This Row],[الحالة بالعربية]] -> Accepted/مقبول | I14: 🟩 #00B050
B15: Rehabilitation | D15: 2 | E15: مقبول شرطي | F15: Conditionally Accepted | G15: الموافقة مشروطة باستكمال أو تصحيح بعض المتطلبات | H15: =tbl_Assessment_Status[[#This Row],[الحالة بالإنجليزية]]&"/"&tbl_Assessment_Status[[#This Row],[الحالة بالعربية]] -> Conditionally Accepted/مقبول شرطي | I15: 🟨 #FFD966
D16: 3 | E16: مرفوض | F16: Rejected | G16: لم تتم الموافقة بسبب عدم استيفاء المعايير أو الأهلية | H16: =tbl_Assessment_Status[[#This Row],[الحالة بالإنجليزية]]&"/"&tbl_Assessment_Status[[#This Row],[الحالة بالعربية]] -> Rejected/مرفوض | I16: 🟥 #FA8697
D19: رقم | E19: الحالة بالعربية | F19: الحالة بالإنجليزية | G19: House Status | H19: كود اللون
D20: 2 | E20: الترميم متوقف بشكل مؤقت | F20: Temporarily Suspended | G20: =tbl_House_Status[[#This Row],[الحالة بالإنجليزية]]&"/"&tbl_House_Status[[#This Row],[الحالة بالعربية]] -> Temporarily Suspended/الترميم متوقف بشكل مؤقت | H20: 🟨 #ED7D31
D21: 3 | E21: قيد الترميم | F21: Under Rehabilitation | G21: =tbl_House_Status[[#This Row],[الحالة بالإنجليزية]]&"/"&tbl_House_Status[[#This Row],[الحالة بالعربية]] -> Under Rehabilitation/قيد الترميم | H21: 🟧 #1DB9C3
D22: 4 | E22: تم الانتهاء من الترميم | F22: Rehabilitation Completed | G22: =tbl_House_Status[[#This Row],[الحالة بالإنجليزية]]&"/"&tbl_House_Status[[#This Row],[الحالة بالعربية]] -> Rehabilitation Completed/تم الانتهاء من الترميم | H22: 🟩 #00B050

Sheet 181-UNDP Houses Rehab Applic
A1: _index | B1: تاريخ الارسال | C1: الاسم الأول | D1: اسم الأب | E1: الكنية | F1: اسم الأم كما هو مذكور في الهوية | G1: الجنس | H1: تاريخ الميلاد كما هو مذكور في الهوية | I1: الحالة الاجتماعية | J1: الاسم الثلاثي للزوج أو الزوجة (إن وجد) | K1: نوع الوثيقة الشخصية | L1: يرجى تحديد نوع الوثيقة في حال اختيار “أخرى” | M1: رقم الوثيقة الشخصية (الرقم الوطني) | N1: صورة الوثيقة الشخصية (الوجه الأول) | O1: صورة الوثيقة الشخصية (الوجه الأول)_URL | P1: صورة الوثيقة الشخصية (الوجه الثاني) | Q1: صورة الوثيقة الشخصية (الوجه الثاني)_URL | R1: المحافظة | S1: المنطقة | T1: الناحية | U1: العنوان التفصيلي لمكان السكن الحالي | V1: رقم الهاتف الرئيسي (واتساب إن أمكن) | W1: رقم هاتف بديل (إضافي) | X1: هل مالك المنزل من الأشخاص ذوي الإعاقة؟ | Y1: يرجى تحديد نوع الإعاقة (في حال الإجابة بنعم) | Z1: يرجى تحديد نوع الإعاقة (في حال الإجابة بنعم)/باستخدام اللغة المعتادة ، هل تجد صعوبة في التواصل ، على سبيل المثال الفهم على الناس أو أن يفهمك الناس؟ | AA1: يرجى تحديد نوع الإعاقة (في حال الإجابة بنعم)/هل تجد صعوبة في الرؤية حتى لو كنت ترتدي نظارة؟ | AB1: يرجى تحديد نوع الإعاقة (في حال الإجابة بنعم)/هل لديك صعوبة في السمع ، حتى لو كنت تستخدم المعينات السمعية؟ | AC1: يرجى تحديد نوع الإعاقة (في حال الإجابة بنعم)/هل تجد صعوبة في المشي أو صعود السلم؟ | AD1: يرجى تحديد نوع الإعاقة (في حال الإجابة بنعم)/هل تجد صعوبة في التذكر أو التركيز؟ | AE1: يرجى تحديد نوع الإعاقة (في حال الإجابة بنعم)/هل لديك صعوبة في الرعاية الذاتية ، مثل غسل الملابس أو ارتداء الملابس؟ | AF1: درجة الصعوبة في التواصل مع الآخرين | AG1: درجة الصعوبة في الرؤية | AH1: درجة الصعوبة في السمع | AI1: درجة الصعوبة في الحركة | AJ1: درجة الصعوبة في التركيز أو التذكر | AK1: درجة الصعوبة في الرعاية الذاتية | AL1: هل تعاني من أمراض مزمنة؟ | AM1: يرجى تحديد نوع أو أنواع الأمراض المزمنة | AN1: يرجى تحديد نوع أو أنواع الأمراض المزمنة/سكري | AO1: يرجى تحديد نوع أو أنواع الأمراض المزمنة/قلب | AP1: يرجى تحديد نوع أو أنواع الأمراض المزمنة/صرع | AQ1: يرجى تحديد نوع أو أنواع الأمراض المزمنة/روماتيزم | AR1: يرجى تحديد نوع أو أنواع الأمراض المزمنة/اخرى | AS1: ملاحظات إضافية تتعلق بالحالة الصحية (إن وجدت) | AT1: نوع معيل الأسرة | AU1: عدد العائلات المقيمة في نفس المنزل | AV1: عدد أفراد الأسرة (بما فيهم مالك المنزل) | AW1: <span style="background-color:#CD6155; color:white"> تفاصيل أفراد الاسرة </span> | AX1: عدد الرجال (العمر أكبر من 18 سنة) | AY1: عدد النساء (العمر أكبر من 18 سنة) | AZ1: عدد الشباب الذكور (من 12 إلى 17 سنة) | BA1: عدد الفتيات الإناث (من 12 إلى 17 سنة) | BB1: عدد الأطفال الذكور (دون سن 12 سنة) | BC1: عدد الأطفال الإناث (دون سن 12 سنة) | BD1: عدد أفراد الأسرة من كبار السن (60 سنة فأكثر) | BE1: عدد النساء المرضعات | BF1: عدد النساء الحوامل | BG1: عدد النساء المطلقات | BH1: عدد النساء الأرامل | BI1: عدد الأطفال المنفصلين عن ذويهم | BJ1: عدد أفراد الأسرة من ذوي الإعاقة | BK1: ما هو مصدر الدخل الرئيسي للأسرة؟ | BL1: عدد الأفراد العاملين في الأسرة | BM1: ما هي حالة إقامتك في المنطقة؟ | BN1: القرية | BO1: عنوان المنزل الكامل | BP1: _إحداثيات الموقع الجغرافي للمنزل (GPS)_latitude | BQ1: _إحداثيات الموقع الجغرافي للمنزل (GPS)_longitude | BR1: حالة الاقامة في المنزل | BS1: هل لديك وثيقة اثبات ملكية حديث؟ | BT1: نوع وثيقة الملكية | BU1: تاريخ إصدار وثيقة الملكية | BV1: صورة وثيقة الملكية | BW1: صورة وثيقة الملكية_URL | BX1: نوع المنزل | BY1: عدد الغرف (بما فيها الصالون) | BZ1: رقم الطابق الذي يقع فيه المنزل | CA1: مساحة المنزل بالمتر المربع | CB1: هل يملك المنزل أو الشقة جدرانًا خارجية سليمة ولا يحتاج إلى أعمال بناء (بلوك) خارجية؟ | CC1: هل يملك المنزل أو الشقة جدرانًا داخلية مكتملة ولا يحتاج إلى أعمال بناء (بلوك) داخلية؟ | CD1: هل يملك المنزل أو الشقة سقفًا وسلالم (أدراج) سليمة؟ | CE1: هل توجد أية أضرار إنشائية في المنزل أو الشقة؟ | CF1: هل المرافق (المياه والصرف) عاملة أم مجرد بناء؟ | CG1: هل المنزل موصول بنظام صرف صحي أو حفرة فنية؟ | CH1: هل مستوى المنزل أخفض من مستوى الأرض (قبو)؟ | CI1: هل المنزل عبارة عن ملحق؟ | CJ1: وصف حالة الضرر من وجهة نظرك كمالك للمنزل | CK1: صورة الواجهة الأمامية للمنزل | CL1: صورة الواجهة الأمامية للمنزل_URL | CM1: صورة للمنزل من الداخل | CN1: صورة للمنزل من الداخل_URL | CO1: صورة توضح حالة الجدران | CP1: صورة توضح حالة الجدران_URL | CQ1: صورة توضح حالة الأعمدة | CR1: صورة توضح حالة الأعمدة_URL | CS1: صورة توضح حالة السقف | CT1: صورة توضح حالة السقف_URL | CU1: صورة توضح حالة المرافق (المطبخ) | CV1: صورة توضح حالة المرافق (المطبخ)_URL | CW1: صورة توضح حالة المرافق (الحمام) | CX1: صورة توضح حالة المرافق (الحمام)_URL | CY1: صورة توضح حالة المرافق (التواليت) | CZ1: صورة توضح حالة المرافق (التواليت)_URL | DA1: هل يتوفر وصول آمن إلى المنزل؟ | DB1: في حال عدم توفر الوصول الآمن، يرجى توضيح الأسباب | DC1: في حال عدم توفر الوصول الآمن، يرجى توضيح الأسباب/مخلفات حرب (ألغام، ذخائر غير منفجرة) | DD1: في حال عدم توفر الوصول الآمن، يرجى توضيح الأسباب/نزاع ملكية أو خلاف قانوني | DE1: في حال عدم توفر الوصول الآمن، يرجى توضيح الأسباب/طريق مسدود بالأنقاض أو الركام | DF1: في حال عدم توفر الوصول الآمن، يرجى توضيح الأسباب/انهيار مبانٍ مجاورة تعيق الوصول | DG1: في حال عدم توفر الوصول الآمن، يرجى توضيح الأسباب/مبانٍ غير مستقرة أو مهددة بالانهيار في الطريق | DH1: في حال عدم توفر الوصول الآمن، يرجى توضيح الأسباب/منطقة عسكرية أو مغلقة | DI1: في حال عدم توفر الوصول الآمن، يرجى توضيح الأسباب/عائق طبيعي (سيول، مجرى مائي، انهيار أرضي) | DJ1: في حال عدم توفر الوصول الآمن، يرجى توضيح الأسباب/سوء حالة الطرق أو انعدام الجسور | DK1: في حال عدم توفر الوصول الآمن، يرجى توضيح الأسباب/مخاطر أمنية أو نشاط مسلح قريب | DL1: في حال عدم توفر الوصول الآمن، يرجى توضيح الأسباب/غير ذلك يرجى تحديده | DM1: يرجى تحديد سبب آخر إن وجد | DN1: هل لدى مالك المنزل طلبات استفادة أخرى ضمن مشاريع مشابهة؟ | DO1: ملاحظات إضافية أو تعليقات عامة (اختياري) | DP1: Contractor
A2: 1 | B2: 45993 | C2: ياسر | D2: محمد | E2: سليمان | F2: وفيقة | G2: ذكر | H2: 24873 | I2: متزوج/ة | J2: ملكة علي الحلاق | K2: أخرى | L2: هوية مجلس محلي | M2: 88616312411 | N2: 1764584951184.jpg | O2: https://eu.kobotoolbox.org/api/v2/assets/asidN676GwD9kVUoocseLY/data/728635896/attachments/attXRYWahxJjPsnEvDBEh7Qf/ | P2: 1764584967477.jpg | Q2: https://eu.kobotoolbox.org/api/v2/assets/asidN676GwD9kVUoocseLY/data/728635896/attachments/att9RS86EenKmMKhqMHcVCec/ | R2: ريف دمشق | S2: مركز ريف دمشق | T2: عربين | U2: حي المزرعة قرب مدرسة المازن | V2: 996832217 | X2: لا | AL2: لا | AT2: غير ذلك | AU2: 2 | AV2: 10 | AX2: 3 | AY2: 3 | AZ2: 0 | BA2: 2 | BB2: 0 | BC2: 2 | BD2: 0 | BE2: 0 | BF2: 0 | BG2: 1 | BH2: 0 | BI2: 1 | BJ2: 0 | BK2: أخرى | BL2: 2 | BM2: عائد من النزوح الداخلي | BN2: زملكا | BO2: حي المزرعة قرب المدرسة | BP2: 33.523905 | BQ2: 36.359193 | BR2: مهجّر عائد | BS2: لا | BX2: منزل مستقل | BY2: 3 | BZ2: 0 | CA2: 70 | CB2: نعم | CC2: نعم | CD2: لا | CE2: لا | CF2: تعمل | CG2: نعم | CH2: لا | CI2: لا | CJ2: ضرر خفيف | CK2: 1764586172363.jpg | CL2: https://eu.kobotoolbox.org/api/v2/assets/asidN676GwD9kVUoocseLY/data/728635896/attachments/attPUxtSBwhonzhfD7eYsD9e/ | CM2: 1764586219989.jpg | CN2: https://eu.kobotoolbox.org/api/v2/assets/asidN676GwD9kVUoocseLY/data/728635896/attachments/attouVW64h6hB2UjtU3poxdV/ | CO2: 1764586266797.jpg | CP2: https://eu.kobotoolbox.org/api/v2/assets/asidN676GwD9kVUoocseLY/data/728635896/attachments/attrWLdNJyfhjpLtFL4vKXei/ | CQ2: 1764586423687.jpg | CR2: https://eu.kobotoolbox.org/api/v2/assets/asidN676GwD9kVUoocseLY/data/728635896/attachments/attPah2tSYfVNpQWKhJ7z5A3/ | CS2: 1764586301492.jpg | CT2: https://eu.kobotoolbox.org/api/v2/assets/asidN676GwD9kVUoocseLY/data/728635896/attachments/att3RRPqS8RXh8BVJX4mU6va/ | CU2: 1764586321473.jpg | CV2: https://eu.kobotoolbox.org/api/v2/assets/asidN676GwD9kVUoocseLY/data/728635896/attachments/attrrpWMnsHdaszsvUR8u7Sk/ | CW2: 1764586346872.jpg | CX2: https://eu.kobotoolbox.org/api/v2/assets/asidN676GwD9kVUoocseLY/data/728635896/attachments/attmefK9GQtZEthGeaYTnWYr/ | CY2: 1764586369281.jpg | CZ2: https://eu.kobotoolbox.org/api/v2/assets/asidN676GwD9kVUoocseLY/data/728635896/attachments/attH5bjgheX27o4xaL4uhNr9/ | DA2: نعم | DN2: لا | DO2: المساعدة ما امكن مع تزكية من المختار | DP2: C3
A3: 2 | B3: 45993 | C3: مهند | D3: محمد جمال | E3: كنهوش | F3: منى | G3: ذكر | H3: 31966 | I3: متزوج/ة | J3: مرفت محمد ازرق | K3: إخراج قيد | M3: 12160045285 | N3: 1764589194191.jpg | O3: https://eu.kobotoolbox.org/api/v2/assets/asidN676GwD9kVUoocseLY/data/728635942/attachments/attjWKQC4TPStVCop7nPg7zb/ | P3: 1764589260084.jpg | Q3: https://eu.kobotoolbox.org/api/v2/assets/asidN676GwD9kVUoocseLY/data/728635942/attachments/attWEWQDN8mnXTvSgyBMpEpd/ | R3: ريف دمشق | S3: مركز ريف دمشق | T3: عربين | U3: حي المزرعة قرب مسجد التوفبق | V3: 942570442 | X3: لا | AL3: نعم | AM3: سكري | AN3: 1 | AO3: 0 | AP3: 0 | AQ3: 0 | AR3: 0 | AT3: غير ذلك | AU3: 1 | AV3: 6 | AX3: 1 | AY3: 1 | AZ3: 0 | BA3: 0 | BB3: 1 | BC3: 3 | BD3: 0 | BE3: 0 | BF3: 0 | BG3: 0 | BH3: 0 | BI3: 0 | BJ3: 0 | BK3: عمل حكومي | BL3: 0 | BM3: عائد من اللجوء الخارجي | BN3: زملكا | BO3: حي المزرعة قرب مسجد التوفيق | BP3: 33.524503 | BQ3: 36.362383 | BR3: مالك | BS3: نعم | BT3: عقد بيع/شراء (كاتب عدل) | BU3: 40415 | BV3: 1764589689210.jpg | BW3: https://eu.kobotoolbox.org/api/v2/assets/asidN676GwD9kVUoocseLY/data/728635942/attachments/att54dQpNVHuPbewD3RTmQTq/ | BX3: شقة طابقية | BY3: 2 | BZ3: 2 | CA3: 45 | CB3: نعم | CC3: نعم | CD3: نعم | CE3: نعم | CF3: لا تعمل | CG3: لا | CH3: لا | CI3: لا | CJ3: ضرر متوسط | CK3: 1764589934698.jpg | CL3: https://eu.kobotoolbox.org/api/v2/assets/asidN676GwD9kVUoocseLY/data/728635942/attachments/attUCJCH7MtPAMqmVhwHTssU/ | CM3: 1764589972392.jpg | CN3: https://eu.kobotoolbox.org/api/v2/assets/asidN676GwD9kVUoocseLY/data/728635942/attachments/att43wnah4CBwkRYYRfEKPtF/ | CO3: 1764590000177.jpg | CP3: https://eu.kobotoolbox.org/api/v2/assets/asidN676GwD9kVUoocseLY/data/728635942/attachments/attud4btVN6ccEPaWFVgqDc2/ | CQ3: 1764590026001.jpg | CR3: https://eu.kobotoolbox.org/api/v2/assets/asidN676GwD9kVUoocseLY/data/728635942/attachments/attDTtFhZtbdj6GSrmH6ooJh/ | CS3: 1764590046586.jpg | CT3: https://eu.kobotoolbox.org/api/v2/assets/asidN676GwD9kVUoocseLY/data/728635942/attachments/attmjR89r64qDpXTtDXHUkAn/ | CU3: 1764590072667.jpg | CV3: https://eu.kobotoolbox.org/api/v2/assets/asidN676GwD9kVUoocseLY/data/728635942/attachments/atteJdzcz95JJVEHXpeQNMkC/ | CW3: 1764590092245.jpg | CX3: https://eu.kobotoolbox.org/api/v2/assets/asidN676GwD9kVUoocseLY/data/728635942/attachments/attzEgRyj6YB9ad8w76hqTy7/ | CY3: 1764590120870.jpg | CZ3: https://eu.kobotoolbox.org/api/v2/assets/asidN676GwD9kVUoocseLY/data/728635942/attachments/attxW5N2qsQAG3edRhzjEP3h/ | DA3: نعم | DN3: لا | DO3: المساعدة ما امكن بتزكية المختار وعضو مكتب تنفيذي | DP3: C3
A4: 3 | B4: 45993 | C4: ميساء | D4: مصطفى | E4: نوح | F4: عائده رحمه | G4: أنثى | H4: 27839 | I4: أرمل/أرملة | K4: هوية شخصية | M4: 3330025285 | N4: 1764587150632.jpg | O4: https://eu.kobotoolbox.org/api/v2/assets/asidN676GwD9kVUoocseLY/data/728642897/attachments/attgDm3sLUrnwWdwFUWmmQ65/ | P4: 1764587160497.jpg | Q4: https://eu.kobotoolbox.org/api/v2/assets/asidN676GwD9kVUoocseLY/data/728642897/attachments/attwBFyvUhe9czM8wNFHaBST/ | R4: ريف دمشق | S4: مركز ريف دمشق | T4: عربين | U4: زملكا المزرعة خلف بيت اب اركيلة | V4: 953240910 | X4: لا | AL4: نعم | AM4: اخرى | AN4: 0 | AO4: 0 | AP4: 0 | AQ4: 0 | AR4: 1 | AS4: مرض الغدة | AT4: غير ذلك | AU4: 1 | AV4: 4 | AX4: 1 | AY4: 2 | AZ4: 0 | BA4: 1 | BB4: 0 | BC4: 0 | BD4: 1 | BE4: 0 | BF4: 0 | BG4: 0 | BH4: 1 | BI4: 0 | BJ4: 1 | BK4: مساعدات إنسانية فقط | BL4: 1 | BM4: عائد من النزوح الداخلي | BN4: زملكا | BO4: زملكا المزرعة خلف بيت ابو اركيلة | BP4: 33.523453 | BQ4: 36.360264 | BR4: مالك | BS4: نعم | BT4: طابو | BU4: 31628 | BV4: 1764587882902.jpg | BW4: https://eu.kobotoolbox.org/api/v2/assets/asidN676GwD9kVUoocseLY/data/728642897/attachments/attwfze2F6abNcieBgpKDp5W/ | BX4: شقة طابقية | BY4: 3 | BZ4: 0 | CA4: 100 | CB4: نعم | CC4: نعم | CD4: نعم | CE4: لا | CF4: تعمل | CG4: نعم | CH4: لا | CI4: لا | CJ4: ضرر خفيف | CK4: 1764587931729.jpg | CL4: https://eu.kobotoolbox.org/api/v2/assets/asidN676GwD9kVUoocseLY/data/728642897/attachments/atticqeCCFnAsEFwUgLMDw6L/ | CM4: 1764587953768.jpg | CN4: https://eu.kobotoolbox.org/api/v2/assets/asidN676GwD9kVUoocseLY/data/728642897/attachments/attJWHFkQRxMnKj8k7paeCkw/ | CO4: 1764587961845.jpg | CP4: https://eu.kobotoolbox.org/api/v2/assets/asidN676GwD9kVUoocseLY/data/728642897/attachments/attXiAtJvhLtAi6rUnmujWU4/ | CQ4: 1764587991502.jpg | CR4: https://eu.kobotoolbox.org/api/v2/assets/asidN676GwD9kVUoocseLY/data/728642897/attachments/attz2amiULvQaFYrk9m67Vqe/ | CS4: 1764587974382.jpg | CT4: https://eu.kobotoolbox.org/api/v2/assets/asidN676GwD9kVUoocseLY/data/728642897/attachments/attTZLtBA3fz85sJfBpeHCPu/ | CU4: 1764588071632.jpg | CV4: https://eu.kobotoolbox.org/api/v2/assets/asidN676GwD9kVUoocseLY/data/728642897/attachments/attjiypVByqnRSAAdZcqqfsw/ | CW4: 1764588036003.jpg | CX4: https://eu.kobotoolbox.org/api/v2/assets/asidN676GwD9kVUoocseLY/data/728642897/attachments/attVyeC3aWvXC89j3kHJC9xY/ | CY4: 1764588049231.jpg | CZ4: https://eu.kobotoolbox.org/api/v2/assets/asidN676GwD9kVUoocseLY/data/728642897/attachments/attB7dffXfpgpUtSr6PTWTfn/ | DA4: نعم | DN4: لا | DP4: C3
A5: 4 | B5: 45993 | C5: محمد محروس | D5: محمد نادر | E5: الزيبق | F5: حميده دياني | G5: ذكر | H5: 22985 | I5: متزوج/ة | J5: سناء خالد السمان | K5: هوية شخصية | M5: 3330038428 | N5: 1764588440238.jpg | O5: https://eu.kobotoolbox.org/api/v2/assets/asidN676GwD9kVUoocseLY/data/728642983/attachments/attk2kbWbxV4SXf29UwujiVf/ | P5: 1764588449538.jpg | Q5: https://eu.kobotoolbox.org/api/v2/assets/asidN676GwD9kVUoocseLY/data/728642983/attachments/attqQSnyb2zos5NFjqRQMAt2/ | R5: ريف دمشق | S5: مركز ريف دمشق | T5: عربين | U5: زملكا المزرعة جانب جامع التوفيق | V5: 931607885 | X5: لا | AL5: نعم | AM5: قلب | AN5: 0 | AO5: 1 | AP5: 0 | AQ5: 0 | AR5: 0 | AT5: منزل يعيله رجل كبير بالسن (فوق 60 سنة) | AU5: 1 | AV5: 8 | AX5: 3 | AY5: 5 | AZ5: 0 | BA5: 0 | BB5: 0 | BC5: 0 | BD5: 0 | BE5: 0 | BF5: 0 | BG5: 0 | BH5: 0 | BI5: 0 | BJ5: 0 | BK5: لا يوجد مصدر دخل | BL5: 2 | BM5: مقيم ولم أنزح | BN5: زملكا | BO5: زملكا المزرعة جنب جامع التوفيق | BP5: 33.5236 | BQ5: 36.361552 | BR5: مالك | BS5: نعم | BT5: حكم محكمة | BU5: 36288 | BV5: 1764588791108.jpg | BW5: https://eu.kobotoolbox.org/api/v2/assets/asidN676GwD9kVUoocseLY/data/728642983/attachments/attRo4CviAYuUKZQqWtsmvom/ | BX5: شقة طابقية | BY5: 2 | BZ5: 3 | CA5: 65 | CB5: نعم | CC5: نعم | CD5: نعم | CE5: لا | CF5: تعمل | CG5: نعم | CH5: لا | CI5: نعم | CJ5: ضرر متوسط | CK5: 1764588853548.jpg | CL5: https://eu.kobotoolbox.org/api/v2/assets/asidN676GwD9kVUoocseLY/data/728642983/attachments/att92dFkXmvTTjFokkBrTVQd/ | CM5: 1764588865251.jpg | CN5: https://eu.kobotoolbox.org/api/v2/assets/asidN676GwD9kVUoocseLY/data/728642983/attachments/atti7S9bQvAgQjBBfubcFwmk/ | CO5: 1764588872898.jpg | CP5: https://eu.kobotoolbox.org/api/v2/assets/asidN676GwD9kVUoocseLY/data/728642983/attachments/attjdiJYVf6TSdTGw4NBNvo5/ | CQ5: 1764588884152.jpg | CR5: https://eu.kobotoolbox.org/api/v2/assets/asidN676GwD9kVUoocseLY/data/728642983/attachments/attKgPYY7edJoh2W7M4fETHj/ | CS5: 1764588891273.jpg | CT5: https://eu.kobotoolbox.org/api/v2/assets/asidN676GwD9kVUoocseLY/data/728642983/attachments/attGjXksUGU4qL8E5qmJeytU/ | CU5: 1764588904267.jpg | CV5: https://eu.kobotoolbox.org/api/v2/assets/asidN676GwD9kVUoocseLY/data/728642983/attachments/attUjxMJoBLkhq2sBYDGNu3K/ | CW5: 1764588913919.jpg | CX5: https://eu.kobotoolbox.org/api/v2/assets/asidN676GwD9kVUoocseLY/data/728642983/attachments/attELGbZMBqcX5kmVxDf8vV6/ | CY5: 1764588922778.jpg | CZ5: https://eu.kobotoolbox.org/api/v2/assets/asidN676GwD9kVUoocseLY/data/728642983/attachments/attQHXMV4tQ5jis8JXsCaaF2/ | DA5: نعم | DN5: لا | DP5: C3
A6: 5 | B6: 45993 | C6: ضياء | D6: حسن | E6: الزو | F6: نجاح الزو | G6: ذكر | H6: 27898 | I6: متزوج/ة | J6: ندى زياد الزو | K6: هوية شخصية | M6: 3330039882 | N6: 1764660224122.jpg | O6: https://eu.kobotoolbox.org/api/v2/assets/asidN676GwD9kVUoocseLY/data/728688491/attachments/attWQGX3F56wDyFoRM7s7pD6/ | P6: 1764660258205.jpg | Q6: https://eu.kobotoolbox.org/api/v2/assets/asidN676GwD9kVUoocseLY/data/728688491/attachments/attPrwDAF4JHsRsaYCPHx8VH/ | R6: ريف دمشق | S6: مركز ريف دمشق | T6: عربين | U6: زملكا خلف المقسم بناء ابو عاطف الدحلة | V6: 963931800465 | W6: 958926814 | X6: لا | AL6: نعم | AM6: اخرى سكري | AN6: 1 | AO6: 0 | AP6: 0 | AQ6: 0 | AR6: 1 | AS6: ديسك رقبة | AT6: غير ذلك | AU6: 1 | AV6: 5 | AX6: 2 | AY6: 2 | AZ6: 0 | BA6: 1 | BB6: 0 | BC6: 0 | BD6: 0 | BE6: 0 | BF6: 0 | BG6: 0 | BH6: 0 | BI6: 0 | BJ6: 0 | BK6: أعمال حرة | BL6: 2 | BM6: عائد من اللجوء الخارجي | BN6: زملكا | BO6: خلف المقسم بناء ابو عاطف دحلة | BP6: 33.523885 | BQ6: 36.355723 | BR6: مالك | BS6: لا | BX6: شقة طابقية | BY6: 3 | BZ6: 4 | CA6: 100 | CB6: لا | CC6: نعم | CD6: نعم | CE6: لا | CF6: تعمل | CG6: نعم | CH6: لا | CI6: لا | CJ6: ضرر خفيف | CK6: 1764660574436.jpg | CL6: https://eu.kobotoolbox.org/api/v2/assets/asidN676GwD9kVUoocseLY/data/728688491/attachments/attVDNoKrsKaoSFJ5CH3haTF/ | CM6: 1764660597148.jpg | CN6: https://eu.kobotoolbox.org/api/v2/assets/asidN676GwD9kVUoocseLY/data/728688491/attachments/attkkG93ofKvNW93cpNm7TS9/ | CO6: 1764660603207.jpg | CP6: https://eu.kobotoolbox.org/api/v2/assets/asidN676GwD9kVUoocseLY/data/728688491/attachments/attc3p4XrioyaFuAQatzbMTS/ | CQ6: 1764660615764.jpg | CR6: https://eu.kobotoolbox.org/api/v2/assets/asidN676GwD9kVUoocseLY/data/728688491/attachments/attyiwPGoE9XLRhTg8LfwMTx/ | CS6: 1764660627271.jpg | CT6: https://eu.kobotoolbox.org/api/v2/assets/asidN676GwD9kVUoocseLY/data/728688491/attachments/att4P9asKiujCKF5TxGvLQmS/ | CU6: 1764660646788.jpg | CV6: https://eu.kobotoolbox.org/api/v2/assets/asidN676GwD9kVUoocseLY/data/728688491/attachments/att5wrihDbUy3CucTYru7FUu/ | CW6: 1764660656327.jpg | CX6: https://eu.kobotoolbox.org/api/v2/assets/asidN676GwD9kVUoocseLY/data/728688491/attachments/attSYP2Lp3hpgUqDvCSoeUvE/ | CY6: 1764660664226.jpg | CZ6: https://eu.kobotoolbox.org/api/v2/assets/asidN676GwD9kVUoocseLY/data/728688491/attachments/atttD6bYX6izFn7z5u29XMQY/ | DA6: نعم | DN6: لا | DO6: لا يوجد | DP6: C3
A7: 6 | B7: 45993 | C7: عفاف | D7: علي | E7: مكاوي | F7: الفات العجلاني | G7: أنثى | H7: 25539 | I7: مطلق/مطلقة | K7: هوية شخصية | M7: 3330004915 | N7: 1764662158773.jpg | O7: https://eu.kobotoolbox.org/api/v2/assets/asidN676GwD9kVUoocseLY/data/728690320/attachments/atta9bYcu8moGLRFpnPkdNk8/ | P7: 1764662183725.jpg | Q7: https://eu.kobotoolbox.org/api/v2/assets/asidN676GwD9kVUoocseLY/data/728690320/attachments/attqQrJnMa8EYZMwaHcAvDrp/ | R7: ريف دمشق | S7: مركز ريف دمشق | T7: عربين | U7: شرق جامع الحمزة مبنى الزغلول | V7: 963954297942 | W7: 954297947 | X7: لا | AL7: نعم | AM7: سكري | AN7: 1 | AO7: 0 | AP7: 0 | AQ7: 0 | AR7: 0 | AT7: منزل يعيله إمراة | AU7: 1 | AV7: 2 | AX7: 1 | AY7: 1 | AZ7: 0 | BA7: 0 | BB7: 0 | BC7: 0 | BD7: 0 | BE7: 0 | BF7: 0 | BG7: 0 | BH7: 0 | BI7: 0 | BJ7: 0 | BK7: لا يوجد مصدر دخل | BL7: 0 | BM7: عائد من اللجوء الخارجي | BN7: زملكا | BO7: جامع الحمزة مبنى الزغلول | BP7: 33.524267 | BQ7: 36.355184 | BR7: مالك | BS7: نعم | BT7: عقد بيع/شراء (كاتب عدل) | BU7: 45732 | BV7: 1764662358995.jpg | BW7: https://eu.kobotoolbox.org/api/v2/assets/asidN676GwD9kVUoocseLY/data/728690320/attachments/attbA93PFAvvixqsNy2mZq7V/ | BX7: شقة طابقية | BY7: 2 | BZ7: 3 | CA7: 70 | CB7: نعم | CC7: نعم | CD7: نعم | CE7: لا | CF7: تعمل | CG7: نعم | CH7: لا | CI7: لا | CJ7: ضرر خفيف | CK7: 1764662431728.jpg | CL7: https://eu.kobotoolbox.org/api/v2/assets/asidN676GwD9kVUoocseLY/data/728690320/attachments/attHrS8U24tLTZcirnc4QiWc/ | CM7: 1764662446002.jpg | CN7: https://eu.kobotoolbox.org/api/v2/assets/asidN676GwD9kVUoocseLY/data/728690320/attachments/attAuCSEyzipCAE6X93Xj6Jk/ | CO7: 1764662454642.jpg | CP7: https://eu.kobotoolbox.org/api/v2/assets/asidN676GwD9kVUoocseLY/data/728690320/attachments/atth33AXyMTnAW3JGQCEcqPv/ | CQ7: 1764662468993.jpg | CR7: https://eu.kobotoolbox.org/api/v2/assets/asidN676GwD9kVUoocseLY/data/728690320/attachments/att8zhWPXvmGknHX6xCKZnEf/ | CS7: 1764662477313.jpg | CT7: https://eu.kobotoolbox.org/api/v2/assets/asidN676GwD9kVUoocseLY/data/728690320/attachments/attaMtSevbzPNByxapKg6RGr/ | CU7: 1764662489292.jpg | CV7: https://eu.kobotoolbox.org/api/v2/assets/asidN676GwD9kVUoocseLY/data/728690320/attachments/attmSXqb6XaPPoAZXhzc4Pdm/ | CW7: 1764662508328.jpg | CX7: https://eu.kobotoolbox.org/api/v2/assets/asidN676GwD9kVUoocseLY/data/728690320/attachments/att22PUuGodJYzytM3Z3Utm2/ | CY7: 1764662502465.jpg | CZ7: https://eu.kobotoolbox.org/api/v2/assets/asidN676GwD9kVUoocseLY/data/728690320/attachments/atthafuxjHgrnTGqKGWwbX4r/ | DA7: نعم | DN7: لا | DO7: البناء بحاجة الي أبواب شبابيك دهان سيراميك الأرضيات وكهرباء وإزالة أنقاض | DP7: C3
A8: 7 | B8: 45993 | C8: فايز | D8: بدوي | E8: الشيخ | F8: خديجة أحمد دلال | G8: ذكر | H8: 24127 | I8: متزوج/ة | J8: ناديا أحمد عميري | K8: هوية شخصية | M8: 3330027212 | N8: 1764666388789.jpg | O8: https://eu.kobotoolbox.org/api/v2/assets/asidN676GwD9kVUoocseLY/data/728725963/attachments/attv8WUM6h4YsxjG4WtmeiyK/ | P8: 1764666398657.jpg | Q8: https://eu.kobotoolbox.org/api/v2/assets/asidN676GwD9kVUoocseLY/data/728725963/attachments/attaCMsicvxaM9c9DV8AjDJc/ | R8: ريف دمشق | S8: مركز ريف دمشق | T8: عربين | U8: خلف المقسم أرض البستان | V8: 963995659423 | W8: 939455905 | X8: لا | AL8: لا | AT8: منزل يعيله رجل كبير بالسن (فوق 60 سنة) | AU8: 1 | AV8: 4 | AX8: 1 | AY8: 2 | AZ8: 1 | BA8: 0 | BB8: 0 | BC8: 0 | BD8: 1 | BE8: 0 | BF8: 0 | BG8: 0 | BH8: 0 | BI8: 0 | BJ8: 0 | BK8: لا يوجد مصدر دخل | BL8: 0 | BM8: عائد من النزوح الداخلي | BN8: زملكا | BO8: خلف المقسم أرض البستان | BP8: 33.522247 | BQ8: 36.355323 | BR8: مالك | BS8: لا | BX8: منزل مستقل | BY8: 2 | BZ8: 0 | CA8: 80 | CB8: نعم | CC8: نعم | CD8: نعم | CE8: لا | CF8: تعمل | CG8: نعم | CH8: لا | CI8: لا | CJ8: ضرر خفيف | CK8: 1764666753028.jpg | CL8: https://eu.kobotoolbox.org/api/v2/assets/asidN676GwD9kVUoocseLY/data/728725963/attachments/attqLhBZJSbvpXacZ5qpzwm3/ | CM8: 1764666762236.jpg | CN8: https://eu.kobotoolbox.org/api/v2/assets/asidN676GwD9kVUoocseLY/data/728725963/attachments/att4fQzTFAgneyabJ2knLpPw/ | CO8: 1764666769453.jpg | CP8: https://eu.kobotoolbox.org/api/v2/assets/asidN676GwD9kVUoocseLY/data/728725963/attachments/att8JmuEfoC4qTQs7yrB7rr8/ | CQ8: 1764666784677.jpg | CR8: https://eu.kobotoolbox.org/api/v2/assets/asidN676GwD9kVUoocseLY/data/728725963/attachments/attpeaFeAHyNXf8Z82TP9RMG/ | CS8: 1764666791531.jpg | CT8: https://eu.kobotoolbox.org/api/v2/assets/asidN676GwD9kVUoocseLY/data/728725963/attachments/attJ3vpwpBhKEFVX83zf6eq4/ | CU8: 1764666811744.jpg | CV8: https://eu.kobotoolbox.org/api/v2/assets/asidN676GwD9kVUoocseLY/data/728725963/attachments/atte3gNNiyeabieVzYE4jnvZ/ | CW8: 1764666850721.jpg | CX8: https://eu.kobotoolbox.org/api/v2/assets/asidN676GwD9kVUoocseLY/data/728725963/attachments/attzMqAZHrAoyuBgjWacWbVV/ | CY8: 1764666824441.jpg | CZ8: https://eu.kobotoolbox.org/api/v2/assets/asidN676GwD9kVUoocseLY/data/728725963/attachments/attLVbJpgDu9ByQzg26C7hNx/ | DA8: نعم | DN8: لا | DO8: البيت بحاجة 3m^3 يبيتون عيار 350 والمطبخ دون سقف رقم المنزل 239 | DP8: C3
A9: 8 | B9: 45993 | C9: مهند | D9: محمد عطا | E9: زيادة | F9: مؤمنة عرفة | G9: ذكر | H9: 28065 | I9: متزوج/ة | J9: ايمان محي الدين الزو | K9: هوية شخصية | M9: 1020000710 | N9: 1764670192259.jpg | O9: https://eu.kobotoolbox.org/api/v2/assets/asidN676GwD9kVUoocseLY/data/728755166/attachments/att8iyy2ccV8D73xbTgMKVy2/ | P9: 1764670205628.jpg | Q9: https://eu.kobotoolbox.org/api/v2/assets/asidN676GwD9kVUoocseLY/data/728755166/attachments/attbizEH75pHikPkhGcYcJX5/ | R9: ريف دمشق | S9: مركز ريف دمشق | T9: عربين | U9: خلف المقسم بناء ابو بشار الزو | V9: 963969285010 | W9: 934658682 | X9: نعم | Y9: باستخدام اللغة المعتادة ، هل تجد صعوبة في التواصل ، على سبيل المثال الفهم على الناس أو أن يفهمك الناس؟ | Z9: 1 | AA9: 0 | AB9: 0 | AC9: 0 | AD9: 0 | AE9: 0 | AF9: لا اعلم | AL9: لا | AT9: غير ذلك | AU9: 1 | AV9: 8 | AX9: 2 | AY9: 3 | AZ9: 1 | BA9: 0 | BB9: 2 | BC9: 0 | BD9: 0 | BE9: 0 | BF9: 0 | BG9: 0 | BH9: 0 | BI9: 0 | BJ9: 0 | BK9: أعمال حرة | BL9: 1 | BM9: عائد من النزوح الداخلي | BN9: زملكا | BO9: خلف المقسم بناء ابو بشار الزو | BP9: 33.523883 | BQ9: 36.355944 | BR9: مالك | BS9: نعم | BT9: عقد بيع/شراء (كاتب عدل) | BU9: 37682 | BV9: 1764670613891.jpg | BW9: https://eu.kobotoolbox.org/api/v2/assets/asidN676GwD9kVUoocseLY/data/728755166/attachments/attbJEmdNbhZs4JLuDWYaruC/ | BX9: شقة طابقية | BY9: 2 | BZ9: 4 | CA9: 100 | CB9: نعم | CC9: نعم | CD9: لا | CE9: لا | CF9: تعمل | CG9: نعم | CH9: لا | CI9: لا | CJ9: ضرر خفيف | CK9: 1764670681989.jpg | CL9: https://eu.kobotoolbox.org/api/v2/assets/asidN676GwD9kVUoocseLY/data/728755166/attachments/attSjZwnc4YBBDe2CJY42fRa/ | CM9: 1764670691388.jpg | CN9: https://eu.kobotoolbox.org/api/v2/assets/asidN676GwD9kVUoocseLY/data/728755166/attachments/attMN2MCv8XtjTy9WY7kodBM/ | CO9: 1764670698839.jpg | CP9: https://eu.kobotoolbox.org/api/v2/assets/asidN676GwD9kVUoocseLY/data/728755166/attachments/att2Myfv7PdZG6NmngajWVQw/ | CQ9: 1764670706527.jpg | CR9: https://eu.kobotoolbox.org/api/v2/assets/asidN676GwD9kVUoocseLY/data/728755166/attachments/attSyvgVqqaK8bc7tVLwNgak/ | CS9: 1764670714370.jpg | CT9: https://eu.kobotoolbox.org/api/v2/assets/asidN676GwD9kVUoocseLY/data/728755166/attachments/attbmVPtApgHWrSNPuFfs8gX/ | CU9: 1764670724583.jpg | CV9: https://eu.kobotoolbox.org/api/v2/assets/asidN676GwD9kVUoocseLY/data/728755166/attachments/attNmpgDmt6RRwFUbJDM4piU/ | CW9: 1764670731967.jpg | CX9: https://eu.kobotoolbox.org/api/v2/assets/asidN676GwD9kVUoocseLY/data/728755166/attachments/attRpXb2WiNH4kjDTuPa8MjC/ | CY9: 1764670740722.jpg | CZ9: https://eu.kobotoolbox.org/api/v2/assets/asidN676GwD9kVUoocseLY/data/728755166/attachments/attzpMRuJekT5Ly5rgqmJpn4/ | DA9: نعم | DN9: لا | DO9: 178 | DP9: C3
A10: 9 | B10: 45993 | C10: علاء الدين | D10: محمد علي | E10: الشيخ | F10: نبيهة الشيخ | G10: ذكر | H10: 22426 | I10: متزوج/ة | J10: نورة الطحان | K10: هوية شخصية | M10: 3330027219 | N10: 1764673503402.jpg | O10: https://eu.kobotoolbox.org/api/v2/assets/asidN676GwD9kVUoocseLY/data/728808254/attachments/att8W3DJwxmaNycGFxxD83s7/ | P10: 1764673515163.jpg | Q10: https://eu.kobotoolbox.org/api/v2/assets/asidN676GwD9kVUoocseLY/data/728808254/attachments/attyqNsPzo5hjbq8VnSJPDhq/ | R10: ريف دمشق | S10: مركز ريف دمشق | T10: عربين | U10: ساحة زملكا | V10: 963958682134 | W10: 953801038 | X10: لا | AL10: لا | AT10: غير ذلك | AU10: 1 | AV10: 3 | AX10: 2 | AY10: 1 | AZ10: 0 | BA10: 0 | BB10: 0 | BC10: 0 | BD10: 0 | BE10: 0 | BF10: 0 | BG10: 0 | BH10: 0 | BI10: 0 | BJ10: 0 | BK10: لا يوجد مصدر دخل | BL10: 2 | BM10: عائد من النزوح الداخلي | BN10: زملكا | BO10: ساحة زملكا | BP10: 33.528889 | BQ10: 36.353392 | BR10: مالك | BS10: نعم | BT10: رخصة بناء | BU10: 36522 | BV10: 1764673750460.jpg | BW10: https://eu.kobotoolbox.org/api/v2/assets/asidN676GwD9kVUoocseLY/data/728808254/attachments/attf5Qid2wjqtpiNFDEEEQ5B/ | BX10: شقة طابقية | BY10: 2 | BZ10: 5 | CA10: 55 | CB10: لا | CC10: لا | CD10: لا | CE10: لا | CF10: تعمل | CG10: نعم | CH10: لا | CI10: لا | CJ10: لا يوجد ضرر | CK10: 1764673796501.jpg | CL10: https://eu.kobotoolbox.org/api/v2/assets/asidN676GwD9kVUoocseLY/data/728808254/attachments/attdijCn6nHfz3iJjwuDVbcD/ | CM10: 1764673808759.jpg | CN10: https://eu.kobotoolbox.org/api/v2/assets/asidN676GwD9kVUoocseLY/data/728808254/attachments/attTv5stifX2JvQnPbSp7MVN/ | CO10: 1764673817442.jpg | CP10: https://eu.kobotoolbox.org/api/v2/assets/asidN676GwD9kVUoocseLY/data/728808254/attachments/attTP3rH4XCpexg7j4uJS5E5/ | CQ10: 1764673829486.jpg | CR10: https://eu.kobotoolbox.org/api/v2/assets/asidN676GwD9kVUoocseLY/data/728808254/attachments/attvApCUsYY6tQMPtr6kC6qT/ | CS10: 1764673839905.jpg | CT10: https://eu.kobotoolbox.org/api/v2/assets/asidN676GwD9kVUoocseLY/data/728808254/attachments/attNpmfyaJ8jVhWFcpEPNPd9/ | CU10: 1764673847713.jpg | CV10: https://eu.kobotoolbox.org/api/v2/assets/asidN676GwD9kVUoocseLY/data/728808254/attachments/attW9JXQGpeZSLokqsVwcmfL/ | CW10: 1764673860005.jpg | CX10: https://eu.kobotoolbox.org/api/v2/assets/asidN676GwD9kVUoocseLY/data/728808254/attachments/att4Xz542wd5wc6TsSRdUXag/ | CY10: 1764673869116.jpg | CZ10: https://eu.kobotoolbox.org/api/v2/assets/asidN676GwD9kVUoocseLY/data/728808254/attachments/att2XZ3XFDC2GrBzrhhYBtnq/ | DA10: نعم | DN10: لا | DO10: 238 | DP10: C3
A11: 10 | B11: 45993 | C11: عبد الرزاق | D11: صبحي | E11: زمزم | F11: أمينة زيدان | G11: ذكر | H11: 21976 | I11: متزوج/ة | J11: عائشة عبد الرحمن الدباس | K11: هوية شخصية | M11: 3330020460 | N11: 1764674939208.jpg | O11: https://eu.kobotoolbox.org/api/v2/assets/asidN676GwD9kVUoocseLY/data/728816194/attachments/attwK4sgrTzTRuWYgps24TCb/ | P11: 1764674949299.jpg | Q11: https://eu.kobotoolbox.org/api/v2/assets/asidN676GwD9kVUoocseLY/data/728816194/attachments/attM74Rs99WFjtjM9ak3ezVk/ | R11: ريف دمشق | S11: مركز ريف دمشق | T11: عربين | U11: محاريب خلف جامع الحسن بناء زمزم | V11: 963967145663 | W11: 944847583 | X11: لا | AL11: لا | AT11: غير ذلك | AU11: 1 | AV11: 4 | AX11: 3 | AY11: 1 | AZ11: 0 | BA11: 0 | BB11: 0 | BC11: 0 | BD11: 0 | BE11: 0 | BF11: 0 | BG11: 0 | BH11: 0 | BI11: 0 | BJ11: 0 | BK11: لا يوجد مصدر دخل | BL11: 2 | BM11: عائد من النزوح الداخلي | BN11: زملكا | BO11: محيريب خلف جامع الحسن بناء زمزم | BP11: 33.526633 | BQ11: 36.352705 | BR11: مالك | BS11: نعم | BT11: بيان قيد عقاري | BU11: 45070 | BV11: 1764675162952.jpg | BW11: https://eu.kobotoolbox.org/api/v2/assets/asidN676GwD9kVUoocseLY/data/728816194/attachments/attJPhTLBMxkEADCsQDvFNsG/ | BX11: شقة طابقية | BY11: 2 | BZ11: 2 | CA11: 55 | CB11: نعم | CC11: نعم | CD11: نعم | CE11: لا | CF11: تعمل | CG11: نعم | CH11: لا | CI11: لا | CJ11: ضرر خفيف | CK11: 1764675221125.jpg | CL11: https://eu.kobotoolbox.org/api/v2/assets/asidN676GwD9kVUoocseLY/data/728816194/attachments/attsbGbLKqBncXE32fMbeHD3/ | CM11: 1764675229027.jpg | CN11: https://eu.kobotoolbox.org/api/v2/assets/asidN676GwD9kVUoocseLY/data/728816194/attachments/attaJEesUWSJPxbeBXwZ8yxB/ | CO11: 1764675240203.jpg | CP11: https://eu.kobotoolbox.org/api/v2/assets/asidN676GwD9kVUoocseLY/data/728816194/attachments/attqeGwhukjsY4WnRP6ZYXXZ/ | CQ11: 1764675250366.jpg | CR11: https://eu.kobotoolbox.org/api/v2/assets/asidN676GwD9kVUoocseLY/data/728816194/attachments/attBCryj3jgavPfq6tUpnhrJ/ | CS11: 1764675257379.jpg | CT11: https://eu.kobotoolbox.org/api/v2/assets/asidN676GwD9kVUoocseLY/data/728816194/attachments/atthVoHRQMLMyLR82pSJB46n/ | CU11: 1764675304071.jpg | CV11: https://eu.kobotoolbox.org/api/v2/assets/asidN676GwD9kVUoocseLY/data/728816194/attachments/atthWPjQQQpurfKtiusa8z8c/ | CW11: 1764675267085.jpg | CX11: https://eu.kobotoolbox.org/api/v2/assets/asidN676GwD9kVUoocseLY/data/728816194/attachments/attYQnvVnUmMzfWUnaeBSDYc/ | CY11: 1764675290593.jpg | CZ11: https://eu.kobotoolbox.org/api/v2/assets/asidN676GwD9kVUoocseLY/data/728816194/attachments/att8jPxrpszPyXwcnXdKwM8E/ | DA11: نعم | DN11: لا | DO11: 8 | DP11: C3
A12: 11 | B12: 45993 | C12: اياد | D12: محمود | E12: محي الدين | F12: فايزه محي الدين | G12: ذكر | H12: 29191 | I12: متزوج/ة | J12: وفاء ابراهيم شيبان | K12: هوية شخصية | M12: 3330012750 | N12: 1764659849024.jpg | O12: https://eu.kobotoolbox.org/api/v2/assets/asidN676GwD9kVUoocseLY/data/728850665/attachments/attUecpBnZniQFEnLn9cb3ux/ | P12: 1764659893073.jpg | Q12: https://eu.kobotoolbox.org/api/v2/assets/asidN676GwD9kVUoocseLY/data/728850665/attachments/attkrAoy5pVT3JdvYa7XogjM/ | R12: ريف دمشق | S12: مركز ريف دمشق | T12: عربين | U12: زملكا جانب الساحة قريب من معهد القيصر | V12: 946670447 | X12: لا | AL12: لا | AT12: غير ذلك | AU12: 1 | AV12: 6 | AX12: 2 | AY12: 2 | AZ12: 1 | BA12: 1 | BB12: 0 | BC12: 0 | BD12: 0 | BE12: 0 | BF12: 0 | BG12: 0 | BH12: 0 | BI12: 0 | BJ12: 0 | BK12: أعمال حرة | BL12: 0 | BM12: نازح حالياً | BN12: زملكا | BO12: زملكا حارة الشوام جانب جامع رضوان | BP12: 33.531639 | BQ12: 36.353237 | BR12: مالك | BS12: نعم | BT12: عقد بيع/شراء (كاتب عدل) | BU12: 38272 | BV12: 1764660166214.jpg | BW12: https://eu.kobotoolbox.org/api/v2/assets/asidN676GwD9kVUoocseLY/data/728850665/attachments/att9hRXhXvrPvpTsVNpcaP77/ | BX12: منزل مستقل | BY12: 2 | BZ12: 0 | CA12: 50 | CB12: لا | CC12: لا | CD12: لا | CE12: لا | CF12: تعمل | CG12: نعم | CH12: لا | CI12: لا | CJ12: ضرر شديد | CK12: 1764660284866.jpg | CL12: https://eu.kobotoolbox.org/api/v2/assets/asidN676GwD9kVUoocseLY/data/728850665/attachments/attbwojQG55TQZY7yS39iNCf/ | CM12: 1764660298471.jpg | CN12: https://eu.kobotoolbox.org/api/v2/assets/asidN676GwD9kVUoocseLY/data/728850665/attachments/att2VGbxfp9BoLovEK3ijhLB/ | CO12: 1764660310733.jpg | CP12: https://eu.kobotoolbox.org/api/v2/assets/asidN676GwD9kVUoocseLY/data/728850665/attachments/attdiTYBvrSt53XtXyyAwX2V/ | CQ12: 1764660322309.jpg | CR12: https://eu.kobotoolbox.org/api/v2/assets/asidN676GwD9kVUoocseLY/data/728850665/attachments/attmzsJk3noq7ufAr2VNCL2J/ | CS12: 1764660329108.jpg | CT12: https://eu.kobotoolbox.org/api/v2/assets/asidN676GwD9kVUoocseLY/data/728850665/attachments/attqBJJxuF7CDA4j9pfvxXFX/ | CU12: 1764660338947.jpg | CV12: https://eu.kobotoolbox.org/api/v2/assets/asidN676GwD9kVUoocseLY/data/728850665/attachments/attNrrfDTztMWspLWabk4W3i/ | CW12: 1764660347859.jpg | CX12: https://eu.kobotoolbox.org/api/v2/assets/asidN676GwD9kVUoocseLY/data/728850665/attachments/attHQYhmA6GAPGC3EH4e6bNE/ | CY12: 1764660357576.jpg | CZ12: https://eu.kobotoolbox.org/api/v2/assets/asidN676GwD9kVUoocseLY/data/728850665/attachments/attV5z2c6NDXGBnzuXYF2Gji/ | DA12: نعم | DN12: لا | DP12: C3
A13: 12 | B13: 45993 | C13: محمدزين | D13: غسان | E13: زين الدين | F13: عبله غنوم | G13: ذكر | H13: 32210 | I13: متزوج/ة | J13: فتحية عامر الصعيدي | K13: هوية شخصية | M13: 3330004901 | N13: 1764661638900.jpg | O13: https://eu.kobotoolbox.org/api/v2/assets/asidN676GwD9kVUoocseLY/data/728851444/attachments/attekkAJBnJZ9MiwJ9NQY5ps/ | P13: 1764661655191.jpg | Q13: https://eu.kobotoolbox.org/api/v2/assets/asidN676GwD9kVUoocseLY/data/728851444/attachments/attJbWvCh6QCrJfwsR4cLNXf/ | R13: ريف دمشق | S13: مركز ريف دمشق | T13: عربين | U13: زملكا خلف الثانوية جنب مولدة شيحا | V13: 960087954 | X13: لا | AL13: لا | AT13: غير ذلك | AU13: 1 | AV13: 5 | AX13: 1 | AY13: 1 | AZ13: 0 | BA13: 0 | BB13: 1 | BC13: 2 | BD13: 0 | BE13: 0 | BF13: 0 | BG13: 0 | BH13: 0 | BI13: 0 | BJ13: 0 | BK13: أعمال حرة | BL13: 1 | BM13: مقيم ولم أنزح | BN13: زملكا | BO13: زملكا خلف ثانوية جانب مولدة شيحا | BP13: 33.529818 | BQ13: 36.351755 | BR13: مالك | BS13: نعم | BT13: بيان قيد عقاري | BU13: 44594 | BV13: 1764661865849.jpg | BW13: https://eu.kobotoolbox.org/api/v2/assets/asidN676GwD9kVUoocseLY/data/728851444/attachments/attAYK4ZquCfYpDavJYgDzjS/ | BX13: منزل مستقل | BY13: 2 | BZ13: 0 | CA13: 100 | CB13: نعم | CC13: نعم | CD13: نعم | CE13: لا | CF13: تعمل | CG13: نعم | CH13: نعم | CI13: لا | CJ13: ضرر خفيف | CK13: 1764661917300.jpg | CL13: https://eu.kobotoolbox.org/api/v2/assets/asidN676GwD9kVUoocseLY/data/728851444/attachments/attm9AgkSrz3S2GJrbqhEEMU/ | CM13: 1764661930087.jpg | CN13: https://eu.kobotoolbox.org/api/v2/assets/asidN676GwD9kVUoocseLY/data/728851444/attachments/attFkHZCTuEsW7u5kP6kCp6j/ | CO13: 1764661938627.jpg | CP13: https://eu.kobotoolbox.org/api/v2/assets/asidN676GwD9kVUoocseLY/data/728851444/attachments/attd5a4xPP3LErWotorVg9zv/ | CQ13: 1764661945835.jpg | CR13: https://eu.kobotoolbox.org/api/v2/assets/asidN676GwD9kVUoocseLY/data/728851444/attachments/attMjvya3a3b7BKmQgwyNBpj/ | CS13: 1764661957262.jpg | CT13: https://eu.kobotoolbox.org/api/v2/assets/asidN676GwD9kVUoocseLY/data/728851444/attachments/attv57f99T8soCNX3GYcxBSg/ | CU13: 1764661972780.jpg | CV13: https://eu.kobotoolbox.org/api/v2/assets/asidN676GwD9kVUoocseLY/data/728851444/attachments/attK26oVCZSfu4srjXMSTXr8/ | CW13: 1764661984691.jpg | CX13: https://eu.kobotoolbox.org/api/v2/assets/asidN676GwD9kVUoocseLY/data/728851444/attachments/att3cBgRFYSFhifFjS8puSqG/ | CY13: 1764661993292.jpg | CZ13: https://eu.kobotoolbox.org/api/v2/assets/asidN676GwD9kVUoocseLY/data/728851444/attachments/attWCq8evtRGvHp3JKSEe8rv/ | DA13: نعم | DN13: لا | DP13: C3
